<?xml version="1.0" ?>
<robot name="turtlebot3_burger" xmlns:xacro="http://ros.org/wiki/xacro">
  <!-- <xacro:include filename="$(find turtlebot3_description)/urdf/common_properties.urdf"/>

  <xacro:property name="r200_cam_rgb_px" value="0.005"/>
  <xacro:property name="r200_cam_rgb_py" value="0.018"/>
  <xacro:property name="r200_cam_rgb_pz" value="0.013"/>
  <xacro:property name="r200_cam_depth_offset" value="0.01"/> -->

  <!-- Init colour -->
  <material name="black">
      <color rgba="0.0 0.0 0.0 1.0"/>
  </material>

  <material name="dark">
    <color rgba="0.3 0.3 0.3 1.0"/>
  </material>

  <material name="light_black">
    <color rgba="0.4 0.4 0.4 1.0"/>
  </material>

  <material name="blue">
    <color rgba="0.0 0.0 0.8 1.0"/>
  </material>

  <material name="green">
    <color rgba="0.0 0.8 0.0 1.0"/>
  </material>

  <material name="grey">
    <color rgba="0.5 0.5 0.5 1.0"/>
  </material>

  <material name="orange">
    <color rgba="1.0 0.4235 0.0392 1.0"/>
  </material>

  <material name="brown">
    <color rgba="0.8706 0.8118 0.7647 1.0"/>
  </material>

  <material name="red">
    <color rgba="0.8 0.0 0.0 1.0"/>
  </material>

  <material name="white">
    <color rgba="1.0 1.0 1.0 1.0"/>
  </material>
  
  <material name="less_white">
    <color rgba="0.8 0.8 0.8 1.0"/>
  </material>

  <link name="base_footprint"/>

  <joint name="base_joint" type="fixed">
    <parent link="base_footprint"/>
    <child link="base_link" />
    <origin xyz="0 0 0.010" rpy="0 0 0"/>
  </joint>

  <link name="base_link">
    <visual>
      <origin xyz="-0.064 0 0.0" rpy="0 0 0"/>
      <geometry>
        <mesh filename="package://turtlebot3_gazebo/models/turtlebot3_common/meshes/waffle_base.dae" scale="0.001 0.001 0.001"/>
      </geometry>
      <material name="blue"/>
    </visual>

    <collision>
      <origin xyz="-0.064 0 0.047" rpy="0 0 0"/>
      <geometry>
        <box size="0.3 0.3 0.15"/>
      </geometry>
    </collision>

    <inertial>
      <origin xyz="0 0 0" rpy="0 0 0"/>
      <mass value="0.000001"/>
      <inertia ixx="0.01" ixy="0" ixz="0"
               iyy="0.01" iyz="0"
               izz="0.02" />

    </inertial>
  </link>
  
  <joint name="upper_box_joint" type="fixed">
    <parent link="base_link"/>
    <child link="upper_box_link" />
    <origin xyz="0 0 0.010" rpy="0 0 0"/>
  </joint>
  
  <link name="upper_box_link">
    <visual>
      <origin xyz="-0.064 0 0.0" rpy="0 0 0"/>
      <geometry>
        <box>
            <size>0.4 0.3 0.15</size> <!-- 자동차 차체의 크기 (길이, 폭, 높이) -->
        </box>
      </geometry>
      <material name="less_white"/>
    </visual>

    <collision>
      <origin xyz="-0.064 0 0.047" rpy="0 0 0"/>
      <geometry>
        <box size="0.2 0.2 0.15"/>
      </geometry>
    </collision>

    <inertial>
      <origin xyz="0 0 0" rpy="0 0 0"/>
      <mass value="0.000001"/>
      <inertia ixx="3.0901903e-03" ixy="-1.5303608e-05" ixz="3.9123493e-05"
               iyy="3.0336793e-03" iyz="-1.2795609e-06"
               izz="0.5228909e-02" />
    </inertial>
  </link>
  
  <joint name="warning_joint" type="fixed">
    <parent link="base_link"/>
    <child link="warning_link" />
    <origin xyz="0 0 0.020" rpy="0 0 0"/>
  </joint>
  <link name="warning_link">
      <!-- 첫 번째 색 (빨간색) -->
      <visual name="warning_visual_red">
          <origin xyz="-0.064 0 0.0" rpy="0 0 0"/>
          <geometry>
              <box>
                 <size>0.05 0.124999 0.05</size> <!-- X: 0.2, Y: 0.15, Z: 0.1 (빨간색 부분) -->
              </box>
          </geometry>
          <material name="red"/>
      </visual>

      <!-- 두 번째 색 (회색) -->
      <visual name="warning_visual_gray">
          <origin xyz="-0.064 0.125 0.0" rpy="0 0 0"/> <!-- 빨간색 박스 뒤에 위치 -->
          <geometry>
              <box>
                  <size>0.05 0.04999 0.05</size> <!-- X: 0.2, Y: 0.05, Z: 0.1 (회색 부분) -->
              </box>
          </geometry>
          <material name="gray"/>
      </visual>

      <!-- 세 번째 색 (파란색) -->
      <visual name="warning_visual_blue">
          <origin xyz="-0.064 0.175 0.0" rpy="0 0 0"/> <!-- 회색 박스 뒤에 위치 -->
          <geometry>
              <box>
                  <size>0.05 0.125 0.05</size> <!-- X: 0.2, Y: 0.15, Z: 0.1 (파란색 부분) -->
              </box>
          </geometry>
          <material name="blue"/>
      </visual>

      <collision>
          <origin xyz="-0.064 0 0.047" rpy="0 0 0"/>
          <geometry>
              <box size="0.266 0.266 0.094"/>
          </geometry>
      </collision>
  
      <inertial>
          <origin xyz="0 0 0" rpy="0 0 0"/>
          <mass value="0.1"/>
          <inertia ixx="8.7002718e-03" ixy="-4.7576583e-05" ixz="1.1160499e-04"
                   iyy="8.6195418e-03" iyz="-3.5422299e-06"
                   izz="1.4612727e-02" />
      </inertial>
  </link>


  <joint name="eye1_joint" type="fixed">
    <parent link="upper_box_link"/>
    <child link="eye1_link" />
    <origin xyz="0 0 0.020" rpy="0 0 0"/>
  </joint>
  <link name="eye1_link">
    <visual>
      <origin xyz="0.2 0.075 0.25" rpy="0 1.5708 0"/>
      <geometry>
          <cylinder>
              <radius>0.03</radius> <!-- 원통의 반지름 -->
              <length>0.001</length> <!-- 원통의 길이 (축 방향) -->
          </cylinder>
      </geometry>
      <material name="white"/>
    </visual>

    <collision>
      <origin xyz="0.2 0.075 0.25" rpy="0 1.5708 0"/>
      <geometry>
        <cylinder>
            <radius>0.03</radius> <!-- 원통의 반지름 -->
            <length>0.001</length> <!-- 원통의 길이 (축 방향) -->
        </cylinder>
      </geometry>
    </collision>

    <inertial>
      <origin xyz="0 0 0" rpy="0 1.5708 0"/>
      <mass value="0.1"/>
      <inertia ixx="8.7002718e-03" ixy="-4.7576583e-05" ixz="1.1160499e-04"
               iyy="8.6195418e-03" iyz="-3.5422299e-06"
               izz="1.4612727e-02" />
    </inertial>
  </link>
  

  <joint name="eye1_1_joint" type="fixed">
    <parent link="eye1_link"/>
    <child link="eye1_1_link" />
    <origin xyz="0 0 0.020" rpy="0 0 0"/>
  </joint>
  <link name="eye1_1_link">
    <visual>
      <origin xyz="0.2001 0.075 0.25" rpy="0 1.5708 0"/>
      <geometry>
          <cylinder>
              <radius>0.003</radius> <!-- 원통의 반지름 -->
              <length>0.001</length> <!-- 원통의 길이 (축 방향) -->
          </cylinder>
      </geometry>
      <material name="black"/>
    </visual>

    <collision>
      <origin xyz="0.2001 0.075 0.25" rpy="0 1.5708 0"/>
      <geometry>
        <cylinder>
            <radius>0.003</radius> <!-- 원통의 반지름 -->
            <length>0.001</length> <!-- 원통의 길이 (축 방향) -->
        </cylinder>
      </geometry>
    </collision>

    <inertial>
      <origin xyz="0 0 0" rpy="0 1.5708 0"/>
      <mass value="0.1"/>
      <inertia ixx="8.7002718e-03" ixy="-4.7576583e-05" ixz="1.1160499e-04"
               iyy="8.6195418e-03" iyz="-3.5422299e-06"
               izz="1.4612727e-02" />
    </inertial>
  </link>

  <joint name="eye2_joint" type="fixed">
    <parent link="upper_box_link"/>
    <child link="eye2_link" />
    <origin xyz="0 0 0.020" rpy="0 0 0"/>
  </joint>
  <link name="eye2_link">
    <visual>
      <origin xyz="0.2 -0.075 0.25" rpy="0 1.5708 0"/>
      <geometry>
          <cylinder>
              <radius>0.03</radius> <!-- 원통의 반지름 -->
              <length>0.001</length> <!-- 원통의 길이 (축 방향) -->
          </cylinder>
      </geometry>
      <material name="white"/>
    </visual>

    <collision>
      <origin xyz="0.2 -0.075 0.25" rpy="0 1.5708 0"/>
      <geometry>
        <cylinder>
            <radius>0.03</radius> <!-- 원통의 반지름 -->
            <length>0.001</length> <!-- 원통의 길이 (축 방향) -->
        </cylinder>
      </geometry>
    </collision>

    <inertial>
      <origin xyz="0 0 0" rpy="0 1.5708 0"/>
      <mass value="0.1"/>
      <inertia ixx="8.7002718e-03" ixy="-4.7576583e-05" ixz="1.1160499e-04"
               iyy="8.6195418e-03" iyz="-3.5422299e-06"
               izz="1.4612727e-02" />
    </inertial>
  </link>
  

  <joint name="eye2_1_joint" type="fixed">
    <parent link="eye2_link"/>
    <child link="eye2_1_link" />
    <origin xyz="0 0 0.020" rpy="0 0 0"/>
  </joint>
  <link name="eye2_1_link">
    <visual>
      <origin xyz="0.2001 -0.075 0.25" rpy="0 1.5708 0"/>
      <geometry>
          <cylinder>
              <radius>0.003</radius> <!-- 원통의 반지름 -->
              <length>0.001</length> <!-- 원통의 길이 (축 방향) -->
          </cylinder>
      </geometry>
      <material name="black"/>
    </visual>

    <collision>
      <origin xyz="0.2001 -0.075 0.25" rpy="0 1.5708 0"/>
      <geometry>
        <cylinder>
            <radius>0.003</radius> <!-- 원통의 반지름 -->
            <length>0.001</length> <!-- 원통의 길이 (축 방향) -->
        </cylinder>
      </geometry>
    </collision>

    <inertial>
      <origin xyz="0 0 0" rpy="0 1.5708 0"/>
      <mass value="0.1"/>
      <inertia ixx="8.7002718e-03" ixy="-4.7576583e-05" ixz="1.1160499e-04"
               iyy="8.6195418e-03" iyz="-3.5422299e-06"
               izz="1.4612727e-02" />
    </inertial>
  </link>

  <joint name="wheel_left_joint" type="continuous">
    <parent link="base_link"/>
    <child link="wheel_left_link"/>
    <origin xyz="0.175 0.144 0.023" rpy="-1.57 0 0"/>
    <axis xyz="0 0 1"/>
  </joint>

  <link name="wheel_left_link">
    <visual>
      <origin xyz="0 0 0" rpy="1.57 0 0"/>
      <geometry>
        <mesh filename="package://turtlebot3_gazebo/models/turtlebot3_common/meshes/tire.dae" scale="0.001 0.001 0.001"/>
      </geometry>
      <material name="black"/>
    </visual>

    <collision>
      <origin xyz="0 0 0" rpy="0 0 0"/>
      <geometry>
        <cylinder length="0.018" radius="0.033"/>
      </geometry>
    </collision>

    <inertial>
      <origin xyz="0 0 0" />
      <mass value="0.15" />
      <inertia ixx="1.1175580e-05" ixy="-4.2369783e-11" ixz="-5.9381719e-09"
               iyy="1.1192413e-05" iyz="-1.4400107e-11"
               izz="2.0712558e-05" />
      </inertial>
  </link>

  <joint name="wheel_right_joint" type="continuous">
    <parent link="base_link"/>
    <child link="wheel_right_link"/>
    <origin xyz="0.175 -0.144 0.023" rpy="-1.57 0 0"/>
    <axis xyz="0 0 1"/>
  </joint>

  <link name="wheel_right_link">
    <visual>
      <origin xyz="0 0 0" rpy="1.57 0 0"/>
      <geometry>
        <mesh filename="package://turtlebot3_gazebo/models/turtlebot3_common/meshes/tire.dae" scale="0.001 0.001 0.001"/>
      </geometry>
      <material name="black"/>
    </visual>

    <collision>
      <origin xyz="0 0 0" rpy="0 0 0"/>
      <geometry>
        <cylinder length="0.018" radius="0.033"/>
      </geometry>
    </collision>

    <inertial>
      <origin xyz="0 0 0" />
      <mass value="0.15" />
      <inertia ixx="1.1175580e-05" ixy="-4.2369783e-11" ixz="-5.9381719e-09"
               iyy="1.1192413e-05" iyz="-1.4400107e-11"
               izz="2.0712558e-05" />
      </inertial>
  </link>

  <joint name="back_wheel_left_joint" type="continuous">
    <parent link="base_link"/>
    <child link="back_wheel_left_link"/>
    <origin xyz="-0.175 0.144 0.023" rpy="-1.57 0 0"/>
    <axis xyz="0 0 1"/>
  </joint>

  <link name="back_wheel_left_link">
    <visual>
      <origin xyz="0 0 0" rpy="1.57 0 0"/>
      <geometry>
        <mesh filename="package://turtlebot3_gazebo/models/turtlebot3_common/meshes/tire.dae" scale="0.001 0.001 0.001"/>
      </geometry>
      <material name="black"/>
    </visual>

    <collision>
      <origin xyz="0 0 0" rpy="0 0 0"/>
      <geometry>
        <cylinder length="0.018" radius="0.033"/>
      </geometry>
    </collision>

    <inertial>
      <origin xyz="0 0 0" />
      <mass value="0.0005" />
      <inertia   ixx="5.5877900e-06" ixy="-2.1184892e-11" ixz="-2.9690859e-09"
                 iyy="5.5962065e-06" iyz="-7.2000535e-12" 
                 izz="1.0356279e-05" />
      </inertial>
  </link>

  <joint name="back_wheel_right_joint" type="continuous">
    <parent link="base_link"/>
    <child link="back_wheel_right_link"/>
    <origin xyz="-0.175 -0.144 0.023" rpy="-1.57 0 0"/>
    <axis xyz="0 0 1"/>
  </joint>

  <link name="back_wheel_right_link">
    <visual>
      <origin xyz="0 0 0" rpy="1.57 0 0"/>
      <geometry>
        <mesh filename="package://turtlebot3_gazebo/models/turtlebot3_common/meshes/tire.dae" scale="0.001 0.001 0.001"/>
      </geometry>
      <material name="black"/>
    </visual>

    <collision>
      <origin xyz="0 0 0" rpy="0 0 0"/>
      <geometry>
        <cylinder length="0.018" radius="0.033"/>
      </geometry>
    </collision>

    <inertial>
      <origin xyz="0 0 0" />
      <mass value="0.0005" />
      <inertia   ixx="5.5877900e-06" ixy="-2.1184892e-11" ixz="-2.9690859e-09"
                 iyy="5.5962065e-06" iyz="-7.2000535e-12" 
                 izz="1.0356279e-05" />
      </inertial>
  </link>
  <joint name="caster_back_left_joint" type="fixed">
    <parent link="base_link"/>
    <child link="caster_back_left_link"/>
    <origin xyz="-0.175 0.1 -0.004" rpy="-1.57 0 0"/>
  </joint>

  <link name="caster_back_left_link">
    <collision>
      <origin xyz="0 0.001 0" rpy="0 0 0"/>
      <geometry>
        <box size="0.030 0.009 0.020"/>
      </geometry>
    </collision>
    
    <inertial>
      <origin xyz="0 0 0" />
      <mass value="0.001" />
      <inertia ixx="0.001" ixy="0.0" ixz="0.0"
               iyy="0.001" iyz="0.0"
               izz="0.001" />
    </inertial>
  </link>
  
  <joint name="caster_back_right_joint" type="fixed">
    <parent link="base_link"/>
    <child link="caster_back_right_link"/>
    <origin xyz="-0.175 -0.1 -0.004" rpy="-1.57 0 0"/>
  </joint>

  <link name="caster_back_right_link">
    <collision>
      <origin xyz="0 0.001 0" rpy="0 0 0"/>
      <geometry>
        <box size="0.030 0.009 0.020"/>
      </geometry>
    </collision>

    <inertial>
      <origin xyz="0 0 0" />
      <mass value="0.001" />
      <inertia ixx="0.001" ixy="0.0" ixz="0.0"
               iyy="0.001" iyz="0.0"
               izz="0.001" />
    </inertial>
  </link>


  <joint name="imu_joint" type="fixed">
    <parent link="base_link"/>
    <child link="imu_link"/>
    <origin xyz="0.0 0 0.068" rpy="0 0 0"/>
  </joint>

  <link name="imu_link"/>

  <joint name="scan_joint" type="fixed">
    <parent link="base_link"/>
    <child link="base_scan"/>
    <origin xyz="0 0 0" rpy="0 0 0"/>
  </joint>

  <link name="base_scan">
    <visual>
      <origin xyz="0 0 0" rpy="0 0 0"/>
      <geometry>
        <mesh filename="package://turtlebot3_gazebo/models/turtlebot3_common/meshes/lds.dae" scale="0.001 0.001 0.001"/>
      </geometry>
      <material name="dark"/>
    </visual>

    <collision>
      <origin xyz="0.015 0 -0.0065" rpy="0 0 0"/>
      <geometry>
        <cylinder length="0.0315" radius="0.055"/>
      </geometry>
    </collision>

    <inertial>
      <mass value="0.1" />
      <origin xyz="0 0 0" />
      <inertia ixx="0.001" ixy="0.0" ixz="0.0"
               iyy="0.001" iyz="0.0"
               izz="0.001" />
    </inertial>
  </link>

  <joint name="camera_joint" type="fixed">
    <origin xyz="0 0 0.43" rpy="0 0 0"/>
    <parent link="base_link"/>
    <child link="camera_link"/>
  </joint>

  <link name="camera_link">
    <visual>
     <origin xyz="0 0 0" rpy="1.57 0 1.57"/>
      <geometry>
       <mesh filename="package://turtlebot3_gazebo/models/turtlebot3_common/meshes/r200.dae" />
      </geometry>
    </visual>
    <collision>
      <origin xyz="0.003 0.065 0.007" rpy="0 0 0"/>
      <geometry>
        <box size="0.012 0.132 0.020"/>
      </geometry>
    </collision>

    <!-- This inertial field needs doesn't contain reliable data!! -->
<!--   <inertial>
      <mass value="0.564" />
      <origin xyz="0 0 0" />
      <inertia ixx="0.003881243" ixy="0.0" ixz="0.0"
               iyy="0.000498940" iyz="0.0"
               izz="0.003879257" />
    </inertial>-->
  </link>

  <joint name="camera_rgb_joint" type="fixed">
    <origin xyz="0.005 0.018 0.013" rpy="0 0 0"/>
    <!-- <origin xyz="${r200_cam_rgb_px} ${r200_cam_rgb_py} ${r200_cam_rgb_pz}" rpy="0 0 0"/> -->
    <parent link="camera_link"/>
    <child link="camera_rgb_frame"/>
  </joint>
  <link name="camera_rgb_frame"/>

  <joint name="camera_rgb_optical_joint" type="fixed">
    <origin xyz="0 0 0" rpy="-1.57 0 -1.57"/>
    <parent link="camera_rgb_frame"/>
    <child link="camera_rgb_optical_frame"/>
  </joint>
  <link name="camera_rgb_optical_frame"/>

  <joint name="camera_depth_joint" type="fixed">
    <origin xyz="0.005 0.028 0.013" rpy="0 0 0"/>
    <!-- <origin xyz="${r200_cam_rgb_px} ${r200_cam_rgb_py + r200_cam_depth_offset} ${r200_cam_rgb_pz}" rpy="0 0 0"/> -->
    <parent link="camera_link"/>
    <child link="camera_depth_frame"/>
  </joint>
  <link name="camera_depth_frame"/>

  <joint name="camera_depth_optical_joint" type="fixed">
    <origin xyz="0 0 0" rpy="-1.57 0 -1.57"/>
    <parent link="camera_depth_frame"/>
    <child link="camera_depth_optical_frame"/>
  </joint>
  <link name="camera_depth_optical_frame"/>

</robot>
