<?xml version="1.0" ?>
<sdf version="1.5">
  <model name="turtlebot3_burger">  
  <pose>0.0 0.0 0.0 0.0 0.0 0.0</pose>

    <link name="base_footprint"/>

    <link name="base_link">
        <inertial>
            <pose>0 0 0.1 0 0 0</pose> <!-- 위치 및 회전 설정 -->
            <inertia>
                <ixx>0.01</ixx> <!-- 관성 모멘트 -->
                <ixy>0</ixy>
                <ixz>0</ixz>
                <iyy>0.01</iyy>
                <iyz>0</iyz>
                <izz>0.02</izz>
            </inertia>
            <mass>0.000001</mass> <!-- 질량 설정 -->
        </inertial>

        <collision name="base_collision">
            <pose>0 0 0.1 0 0 0</pose>
            <geometry>
                <box>
                    <size>0.3 0.3 0.15</size> <!-- 자동차 차체의 크기 (길이, 폭, 높이) -->
                </box>
            </geometry>
        </collision>

        <visual name="base_visual">
            <pose>0 0 0.1 0 0 0</pose>
            <geometry>
                <box>
                    <size>0.6 0.3 0.15</size> <!-- 자동차 차체의 크기 (길이, 폭, 높이) -->
                </box>
            </geometry>
            <material>
                <ambient>0 0 0.8 1</ambient> <!-- 차체 색상 설정 -->
                <diffuse>0 0 0.8 1</diffuse>
            </material>
        </visual>
    </link>
    
    <link name="upper_box_link">
        <collision name="upper_box_collision">
            <pose>0 0 0.25 0 0 0</pose> <!-- base_link 위에 쌓기 위해 z=0.25 설정 -->
            <geometry>
                <box>
                    <size>0.2 0.2 0.15</size> <!-- 박스 크기 (길이, 폭, 높이) -->
                </box>
            </geometry>
        </collision>

        <visual name="upper_box_visual">
            <pose>0 0 0.25 0 0 0</pose> <!-- base_link 위에 쌓기 위해 z=0.25 설정 -->
            <geometry>
                <box>
                    <size>0.4 0.3 0.15</size> <!-- 박스 크기 (길이, 폭, 높이) -->
                </box>
            </geometry>
            <material>
                <ambient>0.8 0.8 0.8 1</ambient> <!-- 색상 설정 -->
                <diffuse>0.8 0.8 0.8 1</diffuse>
            </material>
        </visual>
    </link>

    <link name="warning_link">
        <!-- 첫 번째 색 (빨간색) -->
        <visual name="warning_visual_red">
            <pose>0 -0.085 0.35 0 0 0</pose> <!-- 위 박스에 올려놓기 위해 z=0.35 설정 -->
            <geometry>
                <box>
                    <size>0.05 0.125 0.05</size> <!-- X: 0.2, Y: 0.15, Z: 0.1 (빨간색 부분) -->
                </box>
            </geometry>
            <material>
                <ambient>1 0 0 1</ambient> <!-- 빨간색 -->
                <diffuse>1 0 0 1</diffuse>
            </material>
        </visual>

        <!-- 두 번째 색 (회색) -->
        <visual name="warning_visual_gray">
            <pose>0 0 0.35 0 0 0</pose> <!-- 빨간색 박스 뒤에 위치 -->
            <geometry>
                <box>
                    <size>0.05 0.05 0.05</size> <!-- X: 0.2, Y: 0.05, Z: 0.1 (회색 부분) -->
                </box>
            </geometry>
            <material>
                <ambient>0.5 0.5 0.5 1</ambient> <!-- 회색 -->
                <diffuse>0.5 0.5 0.5 1</diffuse>
            </material>
        </visual>

        <!-- 세 번째 색 (파란색) -->
        <visual name="warning_visual_blue">
            <pose>0 0.085 0.35 0 0 0</pose> <!-- 회색 박스 뒤에 위치 -->
            <geometry>
                <box>
                    <size>0.05 0.125 0.05</size> <!-- X: 0.2, Y: 0.15, Z: 0.1 (파란색 부분) -->
                </box>
            </geometry>
            <material>
                <ambient>0 0 1 1</ambient> <!-- 파란색 -->
                <diffuse>0 0 1 1</diffuse>
            </material>
        </visual>

        <collision name="warning_collision">
            <pose>0 0 0.35 0 0 0</pose> <!-- 위 박스에 올려놓기 위해 z=0.35 설정 -->
            <geometry>
                <box>
                    <size> 0.05 0.35 0.05</size>
                </box> <!-- 전체 박스 크기 (X: 0.2, Y: 0.6, Z: 0.1) -->
            </geometry>
        </collision>
    </link>
    <link name="eye1_link">
        <collision name="eye1_collision">
            <pose>0.2 0.075 0.25 0 1.5708 0</pose> <!-- base_link 위에 쌓기 위해 z=0.25 설정 -->
            <geometry>
                <cylinder>
                    <radius>0.03</radius> <!-- 원통의 반지름 -->
                    <length>0.0001</length> <!-- 원통의 길이 (축 방향) -->
                </cylinder>
            </geometry>
        </collision>

        <visual name="eye1_visual">
            <pose>0.2 0.075 0.25 0 1.5708 0</pose> <!-- base_link 위에 쌓기 위해 z=0.25 설정 -->
            <geometry>
                <cylinder>
                    <radius>0.03</radius> <!-- 원통의 반지름 -->
                    <length>0.001</length> <!-- 원통의 길이 (축 방향) -->
                </cylinder>
            </geometry>
            <material>
                <ambient>1 1 1 1</ambient> <!-- 색상 설정 -->
                <diffuse>1 1 1 1</diffuse>
            </material>
        </visual>
    </link>
    <link name="eye1_1_link">
        <collision name="eye1_1_collision">
            <pose>0.2001 0.075 0.25 0 1.5708 0</pose> 
            <geometry>
                <cylinder>
                    <radius>0.003</radius> <!-- 원통의 반지름 -->
                    <length>0.001</length> <!-- 원통의 길이 (축 방향) -->
                </cylinder>
            </geometry>
        </collision>

        <visual name="eye1_1_visual">
            <pose>0.2001 0.075 0.25 0 1.5708 0</pose> <!-- base_link 위에 쌓기 위해 z=0.25 설정 -->
            <geometry>
                <cylinder>
                    <radius>0.003</radius> <!-- 원통의 반지름 -->
                    <length>0.001</length> <!-- 원통의 길이 (축 방향) -->
                </cylinder>
            </geometry>
            <material>
                <ambient>0 0 0 1</ambient> <!-- 색상 설정 -->
                <diffuse>0 0 0 1</diffuse>
            </material>
        </visual>
    </link>
    
    <link name="eye2_link">
        <collision name="eye2_collision">
            <pose>0.2 -0.075 0.25 0 1.5708 0</pose> <!-- base_link 위에 쌓기 위해 z=0.25 설정 -->
            <geometry>
                <cylinder>
                    <radius>0.03</radius> <!-- 원통의 반지름 -->
                    <length>0.001</length> <!-- 원통의 길이 (축 방향) -->
                </cylinder>
            </geometry>
        </collision>

        <visual name="eye2_visual">
            <pose>0.2 -0.075 0.25 0 1.5708 0</pose> <!-- base_link 위에 쌓기 위해 z=0.25 설정 -->
            <geometry>
                <cylinder>
                    <radius>0.03</radius> <!-- 원통의 반지름 -->
                    <length>0.001</length> <!-- 원통의 길이 (축 방향) -->
                </cylinder>
            </geometry>
            <material>
                <ambient>1 1 1 1</ambient> <!-- 색상 설정 -->
                <diffuse>1 1 1 1</diffuse>
            </material>
        </visual>
    </link>
    
    <link name="eye2_1_link">
        <collision name="eye2_1_collision">
            <pose>0.2001 -0.075 0.25 0 1.5708 0</pose> <!-- base_link 위에 쌓기 위해 z=0.25 설정 -->
            <geometry>
                <cylinder>
                    <radius>0.003</radius> <!-- 원통의 반지름 -->
                    <length>0.001</length> <!-- 원통의 길이 (축 방향) -->
                </cylinder>
            </geometry>
        </collision>

        <visual name="eye2_1_visual">
            <pose>0.2001 -0.075 0.25 0 1.5708 0</pose> <!-- base_link 위에 쌓기 위해 z=0.25 설정 -->
            <geometry>
                <cylinder>
                    <radius>0.003</radius> <!-- 원통의 반지름 -->
                    <length>0.001</length> <!-- 원통의 길이 (축 방향) -->
                </cylinder>
            </geometry>
            <material>
                <ambient>0 0 0 1</ambient> <!-- 색상 설정 -->
                <diffuse>0 0 0 1</diffuse>
            </material>
        </visual>
    </link>
    
    <link name="imu_link">
      <sensor name="tb3_imu" type="imu">
        <always_on>true</always_on>
        <update_rate>200</update_rate>
        <imu>
          <angular_velocity>
            <x>
              <noise type="gaussian">
                <mean>0.0</mean>
                <stddev>2e-4</stddev>
              </noise>
            </x>
            <y>
              <noise type="gaussian">
                <mean>0.0</mean>
                <stddev>2e-4</stddev>
              </noise>
            </y>
            <z>
              <noise type="gaussian">
                <mean>0.0</mean>
                <stddev>2e-4</stddev>
              </noise>
            </z>
          </angular_velocity>
          <linear_acceleration>
            <x>
              <noise type="gaussian">
                <mean>0.0</mean>
                <stddev>1.7e-2</stddev>
              </noise>
            </x>
            <y>
              <noise type="gaussian">
                <mean>0.0</mean>
                <stddev>1.7e-2</stddev>
              </noise>
            </y>
            <z>
              <noise type="gaussian">
                <mean>0.0</mean>
                <stddev>1.7e-2</stddev>
              </noise>
            </z>
          </linear_acceleration>
        </imu>
        <plugin name="turtlebot3_imu" filename="libgazebo_ros_imu_sensor.so">
          <ros>
            <!-- <namespace>/tb3</namespace> -->
            <remapping>~/out:=imu</remapping>
          </ros>
        </plugin>
      </sensor>
    </link>

    <link name="base_scan">    
      <inertial>
        <pose>0 0 0.4 0 0 0</pose>
        <inertia>
          <ixx>0.001</ixx>
          <ixy>0.000</ixy>
          <ixz>0.000</ixz>
          <iyy>0.001</iyy>
          <iyz>0.000</iyz>
          <izz>0.001</izz>
        </inertia>
        <mass>0.1</mass>
      </inertial>

      <collision name="lidar_sensor_collision">
        <pose>0 0 0.4 0 0 0</pose>
        <geometry>
          <cylinder>
            <radius>0.0508</radius>
            <length>0.055</length>
          </cylinder>
        </geometry>
      </collision>

      <visual name="lidar_sensor_visual">
        <pose>-0.012 0 0.41 0 0 0</pose>
        <geometry>
          <mesh>
            <uri>model://turtlebot3_common/meshes/lds.dae</uri>
            <scale>0.001 0.001 0.001</scale>
          </mesh>
        </geometry>
      </visual>

      <sensor name="hls_lfcd_lds" type="ray">
        <always_on>true</always_on>
        <visualize>false</visualize>
        <pose>-0.012 0 0.41 0 0 0</pose>
        <update_rate>5</update_rate>
        <ray>
          <scan>
            <horizontal>
              <samples>360</samples>
              <resolution>1.000000</resolution>
              <min_angle>0.000000</min_angle>
              <max_angle>6.280000</max_angle>
            </horizontal>
          </scan>
          <range>
            <min>0.120000</min>
            <max>3.5</max>
            <resolution>0.015000</resolution>
          </range>
          <noise>
            <type>gaussian</type>
            <mean>0.0</mean>
            <stddev>0.01</stddev>
          </noise>
        </ray>
        <plugin name="turtlebot3_laserscan" filename="libgazebo_ros_ray_sensor.so">
          <ros>
            <!-- <namespace>/tb3</namespace> -->
            <remapping>~/out:=scan</remapping>
          </ros>
          <output_type>sensor_msgs/LaserScan</output_type>
          <frame_name>base_scan</frame_name>
        </plugin>
      </sensor>
    </link>

    <link name="wheel_left_link">

      <inertial>
        <pose>0.175 0.144 0.023 -1.57 0 0</pose>
        <inertia>
          <ixx>1.1175580e-05</ixx>
          <ixy>-4.2369783e-11</ixy>
          <ixz>-5.9381719e-09</ixz>
          <iyy>1.1192413e-05</iyy>
          <iyz>-1.4400107e-11</iyz>
          <izz>2.0712558e-05</izz>
        </inertia>
        <mass>0.15</mass>
      </inertial>

      <collision name="wheel_left_collision">
        <pose>0.175 0.144 0.023 -1.57 0 0</pose>
        <geometry>
          <cylinder>
            <radius>0.033</radius>
            <length>0.018</length>
          </cylinder>
        </geometry>
        <surface>
          <!-- This friction pamareter don't contain reliable data!! -->
          <friction>
            <ode>
              <mu>100000.0</mu>
              <mu2>100000.0</mu2>
              <fdir1>0 0 0</fdir1>
              <slip1>0.0</slip1>
              <slip2>0.0</slip2>
            </ode>
          </friction>
          <contact>
            <ode>
              <soft_cfm>0</soft_cfm>
              <soft_erp>0.2</soft_erp>
              <kp>1e+5</kp>
              <kd>1</kd>
              <max_vel>0.01</max_vel>
              <min_depth>0.001</min_depth>
            </ode>
          </contact>
        </surface>
      </collision>

      <visual name="wheel_left_visual">
        <pose>0.175 0.144 0.023 0 0 0</pose>
        <geometry>
          <mesh>
            <uri>model://turtlebot3_common/meshes/tire.dae</uri>
            <scale>0.001 0.001 0.001</scale>
          </mesh>
        </geometry>
      </visual>
    </link>

    <link name="wheel_right_link">

      <inertial>
        <pose>0.175 -0.144 0.023 -1.57 0 0</pose>
        <inertia>
          <ixx>1.1175580e-05</ixx>
          <ixy>-4.2369783e-11</ixy>
          <ixz>-5.9381719e-09</ixz>
          <iyy>1.1192413e-05</iyy>
          <iyz>-1.4400107e-11</iyz>
          <izz>2.0712558e-05</izz>
        </inertia>
        <mass>0.15</mass>
      </inertial>
    
      <collision name="wheel_right_collision">
        <pose>0.175 -0.144 0.023 -1.57 0 0</pose>
        <geometry>
          <cylinder>
            <radius>0.033</radius>
            <length>0.018</length>
          </cylinder>
        </geometry>
        <surface>
          <!-- This friction pamareter don't contain reliable data!! -->
          <friction>
            <ode>
              <mu>100000.0</mu>
              <mu2>100000.0</mu2>
              <fdir1>0 0 0</fdir1>
              <slip1>0.0</slip1>
              <slip2>0.0</slip2>
            </ode>
          </friction>
          <contact>
            <ode>
              <soft_cfm>0</soft_cfm>
              <soft_erp>0.2</soft_erp>
              <kp>1e+5</kp>
              <kd>1</kd>
              <max_vel>0.01</max_vel>
              <min_depth>0.001</min_depth>
            </ode>
          </contact>
        </surface>
      </collision>

      <visual name="wheel_right_visual">
        <pose>0.175 -0.144 0.023 0 0 0</pose>
        <geometry>
          <mesh>
            <uri>model://turtlebot3_common/meshes/tire.dae</uri>
            <scale>0.001 0.001 0.001</scale>
          </mesh>
        </geometry>
      </visual>
    </link>


    <link name="back_wheel_left_link">

      <inertial>
        <pose>-0.175 0.144 0.023 -1.57 0 0</pose>
        <inertia>
          <ixx>5.5877900e-06</ixx>
          <ixy>-2.1184892e-11</ixy>
          <ixz>-2.9690859e-09</ixz>
          <iyy>5.5962065e-06</iyy>
          <iyz>-7.2000535e-12</iyz>
          <izz>1.0356279e-05</izz>
        </inertia>
        <mass>0.0005</mass>
      </inertial>

      <collision name="back_wheel_left_collision">
        <pose>-0.175 0.144 0.023 -1.57 0 0</pose>
        <geometry>
          <cylinder>
            <radius>0.033</radius>
            <length>0.018</length>
          </cylinder>
        </geometry>
        <surface>
          <!-- This friction pamareter don't contain reliable data!! -->
          <friction>
            <ode>
              <mu>0.0</mu>
              <mu2>0.0</mu2>
              <fdir1>0 0 0</fdir1>
              <slip1>0.0</slip1>
              <slip2>0.0</slip2>
            </ode>
          </friction>
          <contact>
            <ode>
              <soft_cfm>0</soft_cfm>
              <soft_erp>0.2</soft_erp>
              <kp>1e+5</kp>
              <kd>1</kd>
              <max_vel>0.01</max_vel>
              <min_depth>0.001</min_depth>
            </ode>
          </contact>
        </surface>
      </collision>

      <visual name="back_wheel_left_visual">
        <pose>-0.175 0.144 0.023 0 0 0</pose>
        <geometry>
          <mesh>
            <uri>model://turtlebot3_common/meshes/tire.dae</uri>
            <scale>0.001 0.001 0.001</scale>
          </mesh>
        </geometry>
      </visual>
    </link>

    <link name="back_wheel_right_link">

      <inertial>
        <pose>-0.175 -0.144 0.023 -1.57 0 0</pose>
        <inertia>
        <inertia>
          <ixx>5.5877900e-06</ixx>
          <ixy>-2.1184892e-11</ixy>
          <ixz>-2.9690859e-09</ixz>
          <iyy>5.5962065e-06</iyy>
          <iyz>-7.2000535e-12</iyz>
          <izz>1.0356279e-05</izz>
        </inertia>
        <mass>0.0005</mass>
      </inertial>
    
      <collision name="back_wheel_right_collision">
        <pose>-0.175 -0.144 0.023 -1.57 0 0</pose>
        <geometry>
          <cylinder>
            <radius>0.033</radius>
            <length>0.018</length>
          </cylinder>
        </geometry>
        <surface>
          <!-- This friction pamareter don't contain reliable data!! -->
          <friction>
            <ode>
              <mu>0.0</mu>
              <mu2>0.0</mu2>
              <fdir1>0 0 0</fdir1>
              <slip1>0.0</slip1>
              <slip2>0.0</slip2>
            </ode>
          </friction>
          <contact>
            <ode>
              <soft_cfm>0</soft_cfm>
              <soft_erp>0.2</soft_erp>
              <kp>1e+5</kp>
              <kd>1</kd>
              <max_vel>0.01</max_vel>
              <min_depth>0.001</min_depth>
            </ode>
          </contact>
        </surface>
      </collision>

      <visual name="back_wheel_right_visual">
        <pose>-0.175 -0.144 0.023 0 0 0</pose>
        <geometry>
          <mesh>
            <uri>model://turtlebot3_common/meshes/tire.dae</uri>
            <scale>0.001 0.001 0.001</scale>
          </mesh>
        </geometry>
      </visual>
    </link>
    <link name='caster_back_left_link'>
      <pose>-0.175 0.1 -0.004 -1.57 0 0</pose>
      <inertial>
        <mass>0.001</mass>
        <inertia>
          <ixx>0.00001</ixx>
          <ixy>0.000</ixy>
          <ixz>0.000</ixz>
          <iyy>0.00001</iyy>
          <iyz>0.000</iyz>
          <izz>0.00001</izz>
        </inertia>
      </inertial>
      <collision name='collision'>
        <geometry>
          <sphere>
            <radius>0.025000</radius>
          </sphere>
        </geometry>
        <surface>
          <contact>
            <ode>
              <mu>100000.0</mu>
              <mu2>100000.0</mu2>
              <soft_cfm>1e-5</soft_cfm>
              <soft_erp>0.8</soft_erp>
              <kp>1e+5</kp>
              <kd>1</kd>
              <max_vel>0.01</max_vel>
              <min_depth>0.001</min_depth>
            </ode>
          </contact>
        </surface>
      </collision>
    </link>
    
    <link name='caster_back_right_link'>
      <pose>-0.175 -0.1 -0.004 -1.57 0 0</pose>
      <inertial>
        <mass>0.001</mass>
        <inertia>
          <ixx>0.00001</ixx>
          <ixy>0.000</ixy>
          <ixz>0.000</ixz>
          <iyy>0.00001</iyy>
          <iyz>0.000</iyz>
          <izz>0.00001</izz>
        </inertia>
      </inertial>
      <collision name='collision'>
        <geometry>
          <sphere>
            <radius>0.025000</radius>
          </sphere>
        </geometry>
        <surface>
          <contact>
            <ode>
              <mu>100000.0</mu>
              <mu2>100000.0</mu2>
              <soft_cfm>1e-5</soft_cfm>
              <soft_erp>0.8</soft_erp>
              <kp>1e+5</kp>
              <kd>1</kd>
              <max_vel>0.01</max_vel>
              <min_depth>0.001</min_depth>
            </ode>
          </contact>
        </surface>
      </collision>
    </link>


    <link name="camera_link"/>

    <link name="camera_rgb_frame">
      <inertial>
        <pose>0 0 0.43 0 0 0</pose>
        <inertia>
          <ixx>0.001</ixx>
          <ixy>0.000</ixy>
          <ixz>0.000</ixz>
          <iyy>0.001</iyy>
          <iyz>0.000</iyz>
          <izz>0.001</izz>
        </inertia>
        <mass>0.0035</mass>
      </inertial>

      <pose>0 0 0.43 0 0 0</pose>
      <sensor name="camera" type="depth">
       <pose> 0 0 0 0 0 0 </pose>
        <always_on>true</always_on>
        <visualize>true</visualize>
        <update_rate>1</update_rate>
        <camera name="intel_realsense_r200">
           <horizontal_fov>1.02974</horizontal_fov>
          <image>
            <width>640</width>
            <height>480</height>
            <format>B8G8R8</format>
          </image>
          <clip>
               <near>0.05</near>
               <far>8.0</far>
          </clip>
          <noise>
            <type>gaussian</type>

            <mean>0.0</mean>
            <stddev>0.007</stddev>
          </noise>
        </camera>
          <plugin name="camera_driver" filename="libgazebo_ros_camera.so">
            <ros>
            </ros>
          <frame_name>camera_rgb_frame</frame_name>
          <min_depth>0.1</min_depth>
          <max_depth>100</max_depth>

          </plugin>
      </sensor>
    </link>

    
<!--
  <link name="turtlebot3_wall1">
      <visual name="turtlebot3_wall1_visual">>
        <pose>-0.0 0 0 0 0 0</pose>
        <geometry>
         <box>
            <size>0.25 0.25 0.005</size>
         </box>
        </geometry>

        <material>Gazebo/Red</material>
      </visual>
      <collision name="turtlebot3_wall1_collision">
        <pose>-0.0 0 .0 0 0 0</pose>
        <geometry>
          <box>
            <size>0.25 0.25 0.005</size>
         </box>
        </geometry>
      </collision>
    </link>

  <joint name="turtlebot3_wall1_joint" type="fixed">
    <parent>turtlebot3_tray</parent>
      <child>turtlebot3_wall1</child>
    <pose>0.0 0.0 0.0 1.57 1.57 0</pose>
  </joint>
  -->

    <joint name="base_joint" type="fixed">
      <parent>base_footprint</parent>
      <child>base_link</child>
    </joint>
    
    <joint name="upper_box_joint" type="fixed">
      <parent>base_link</parent>
      <child>upper_box_link</child>
    </joint>
    
    <joint name="warning_joint" type="fixed">
      <parent>upper_box_link</parent>
      <child>warning_link</child>
    </joint>
    
    <joint name="eye1_joint" type="fixed">
      <parent>upper_box_link</parent>
      <child>eye1_link</child>
    </joint>

    <joint name="eye1_1_joint" type="fixed">
      <parent>eye1_link</parent>
      <child>eye1_1_link</child>
    </joint>
    
    <joint name="eye2_joint" type="fixed">
      <parent>upper_box_link</parent>
      <child>eye2_link</child>
    </joint>
    
    <joint name="eye2_1_joint" type="fixed">
      <parent>eye2_link</parent>
      <child>eye2_1_link</child>
    </joint>
    
    <joint name="wheel_left_joint" type="revolute">
      <parent>base_link</parent>
      <child>wheel_left_link</child>
      <pose>0.175 0.144 0.023 -1.57 0 0</pose>
      <axis>
        <xyz>0 0 1</xyz>
      </axis>
    </joint>

    <joint name="wheel_right_joint" type="revolute">
      <parent>base_link</parent>
      <child>wheel_right_link</child>
      <pose>0.175 -0.144 0.023 -1.57 0 0</pose>
      <axis>
        <xyz>0 0 1</xyz>
      </axis>
    </joint>
    
    <joint name="back_wheel_left_joint" type="revolute">
      <parent>base_link</parent>
      <child>back_wheel_left_link</child>
      <pose>-0.175 0.144 0.023 -1.57 0 0</pose>
      <axis>
        <xyz>0 0 1</xyz>
      </axis>
    </joint>

    <joint name="back_wheel_right_joint" type="revolute">
      <parent>base_link</parent>
      <child>back_wheel_right_link</child>
      <pose>-0.175 -0.144 0.023 -1.57 0 0</pose>
      <axis>
        <xyz>0 0 1</xyz>
      </axis>
    </joint>

    <joint name='caster_back_right_joint' type='ball'>
      <parent>base_link</parent>
      <child>caster_back_right_link</child>
    </joint>

    <joint name='caster_back_left_joint' type='ball'>
      <parent>base_link</parent>
      <child>caster_back_left_link</child>
    </joint>

    <joint name="imu_joint" type="fixed">
      <parent>base_link</parent>
      <child>imu_link</child>
      <pose>0 0 0.4 0 0 0</pose>
      <axis>
        <xyz>0 0 1</xyz>
      </axis>
    </joint>    

    <joint name="lidar_joint" type="fixed">
      <parent>base_link</parent>
      <child>base_scan</child>
      <pose>0 0 0.4 0 0 0</pose>
      <axis>
        <xyz>0 0 1</xyz>
      </axis>
    </joint>

    <joint name="camera_joint" type="fixed">
      <parent>base_link</parent>
      <child>camera_link</child>
      <pose>0 0 0.43 0 0 0</pose>
      <axis>
        <xyz>0 0 1</xyz>
      </axis>
    </joint>

    <joint name="camera_rgb_joint" type="fixed">
      <parent>camera_link</parent>
      <child>camera_rgb_frame</child>
      <pose>0 0 0.43 1 0 0</pose>
      <axis>
        <xyz>0 0 1</xyz>
      </axis>
    </joint>

    <plugin name="turtlebot3_diff_drive" filename="libgazebo_ros_diff_drive.so">

      <ros>
        <!-- <namespace>/robot0</namespace> -->
        <remapping>/tf:=tf</remapping>
      </ros>

      <update_rate>30</update_rate>
      <left_joint>wheel_left_joint</left_joint>
      <right_joint>wheel_right_joint</right_joint>

      <wheel_separation>0.287</wheel_separation>
      <wheel_diameter>0.066</wheel_diameter>

      <max_wheel_torque>20</max_wheel_torque>
      <max_wheel_acceleration>1.0</max_wheel_acceleration>

      <command_topic>cmd_vel</command_topic>

      <publish_odom>true</publish_odom>
      <publish_odom_tf>true</publish_odom_tf>
      <publish_wheel_tf>false</publish_wheel_tf>

      <odometry_topic>odom</odometry_topic>
      <odometry_frame>odom</odometry_frame>
      <robot_base_frame>base_footprint</robot_base_frame>

    </plugin>

    <plugin name="turtlebot3_joint_state" filename="libgazebo_ros_joint_state_publisher.so">
      <ros>
        <!-- <namespace>/tb3</namespace> -->
        <remapping>~/out:=joint_states</remapping>
      </ros>
      <update_rate>30</update_rate>
      <joint_name>wheel_left_joint</joint_name>
      <joint_name>wheel_right_joint</joint_name>
    </plugin>    

  </model>
</sdf>
